Workbook

Sheet HOW TO USE
B1: Tracking documentation
B3: Documenting a flow
B4: 1. Right-click the FLOW TEMPLATE tab → Move or Copy → tick 'Create a copy' → OK. Rename the copy, e.g. 'Transfer Flow'.
B5: 2. Fill the flow name, owner and date at the top of the sheet.
B6: 3. Each screen block has a title row (screen key + screen name) and 8 event rows next to one merged IMAGE cell.
B7: 4. Screenshot: select the IMAGE cell → Insert → Pictures → Place in Cell (Excel 365). The picture stays inside the cell when rows are added or sorted.
B8: 5. EVENT TYPE has a drop-down with every tracker in the JSON. Write one event per row.
B9: 6. Several parameters or values: put each on its own line in the same cell (Windows: Alt+Enter · Mac: Option+Return), so they line up with each other.
B10: 7. An event fired several times with different values: list all distinct values in VALUE, one per line.
B11: 8. Need more rows in a screen? Insert rows inside the block (above its last row); the IMAGE cell grows with them. Need more blocks? Copy a whole empty block (title row + rows) and paste it below.
B13: Tracking progress
B14: 9. When an event is documented in any flow sheet, open SUMMARY and pick ✓ in the Done column of its row. Optionally write the flow name in 'Documented in'.
... B22: • SUMMARY and PROGRESS only use formulas inside this workbook, so both sheets can be copied into another workbook (Move or Copy → To book).

Sheet FLOW TEMPLATE
A1: FLOW NAME
A2: Owner: | C2: Last updated: | E2: Rename this sheet to the flow name
A4: IMAGE | B4: EVENT TYPE | C4: EVENT NAME | D4: EVENT PARAMETERS | E4: VALUE | F4: NOTES
A5: #1 Screen key › | D5: Screen name ›
A6: paste screenshot (Insert › Pictures › Place in Cell)
A15: #2 Screen key › | D15: Screen name ›
A16: paste screenshot (Insert › Pictures › Place in Cell)
A25: #3 Screen key › | D25: Screen name ›
A26: paste screenshot (Insert › Pictures › Place in Cell)
A35: #4 Screen key › | D35: Screen name ›
A36: paste screenshot (Insert › Pictures › Place in Cell)
A45: #5 Screen key › | D45: Screen name ›
A46: paste screenshot (Insert › Pictures › Place in Cell)
A55: #6 Screen key › | D55: Screen name ›
A56: paste screenshot (Insert › Pictures › Place in Cell)
A65: #7 Screen key › | D65: Screen name ›
A66: paste screenshot (Insert › Pictures › Place in Cell)
A75: #8 Screen key › | D75: Screen name ›
A76: paste screenshot (Insert › Pictures › Place in Cell)
A85: #9 Screen key › | D85: Screen name ›
A86: paste screenshot (Insert › Pictures › Place in Cell)
A95: #10 Screen key › | D95: Screen name ›
A96: paste screenshot (Insert › Pictures › Place in Cell)
A105: #11 Screen key › | D105: Screen name ›
A106: paste screenshot (Insert › Pictures › Place in Cell)
A115: #12 Screen key › | D115: Screen name ›
A116: paste screenshot (Insert › Pictures › Place in Cell)
A125: #13 Screen key › | D125: Screen name ›
A126: paste screenshot (Insert › Pictures › Place in Cell)
A135: #14 Screen key › | D135: Screen name ›
A136: paste screenshot (Insert › Pictures › Place in Cell)
A145: #15 Screen key › | D145: Screen name ›
A146: paste screenshot (Insert › Pictures › Place in Cell)
A155: #16 Screen key › | D155: Screen name ›
A156: paste screenshot (Insert › Pictures › Place in Cell)
A165: #17 Screen key › | D165: Screen name ›
A166: paste screenshot (Insert › Pictures › Place in Cell)
A175: #18 Screen key › | D175: Screen name ›
A176: paste screenshot (Insert › Pictures › Place in Cell)
A185: #19 Screen key › | D185: Screen name ›
...

Sheet SUMMARY
A1: SUMMARY · every key in the JSON
A2: Pick ✓ in Done when the key is documented in a flow sheet. Filter Done = (Blanks) for the to-do list. Keys whose name continues a screen key are indented under it.
A4: Done | B4: Feature | C4: Key | D4: Type | E4: Firebase | F4: Amplitude | G4: Appsflyer | H4: MarketingCloud | I4: Evergage | J4: Parameters | K4: Documented in | L4: Notes
B5: Login | C5: visitLoginUser | D5: Screen | E5: LoginUserScreen | F5: login user viewed
B6: Login | C6: hitLoginUserNext | D6: Event · hit | E6: LoginUser_Next_Tapped | F6: login next clicked | J6: username_type, input_type
B7: Login | C7: hitForgotUsername | D7: Event · hit | E7: LoginUser_ForgotUsername_Tapped
B8: Login | C8: visitLoginPassword | D8: Screen | E8: LoginPasswordScreen
B9: Login | C9: hitLoginPassword | D9: Event · hit | E9: LoginPassword_Masuk_Tapped | G9: Login
B10: Login | C10: successLogin | D10: Event · success | E10: Login_Success | F10: login success | G10: af_login | H10: LoginSuccess | J10: login_method
B11: Intro Biometric | C11: visitIntroBiometric | D11: Screen | E11: IntroBiometricScreen
B12: Intro Biometric | C12: hitBiometricActivate | D12: Event · hit | E12: Intro_Biometric_Setup_Activate_Button_Tapped | F12: biometric activate clicked
B13: Intro Biometric | C13: hitBiometricLater | D13: Event · hit | E13: IntroBiometric_Later_Tapped
B14: Registration | C14: visitRegistrationForm | D14: Screen | E14: RegistrationFormScreen
B15: Registration | C15: hitRegistrationSubmit | D15: Event · hit | E15: Registration_Submit_Tapped | G15: af_complete_registration | J15: registration_type, referral_code, af_registration_method
B16: Create Password | C16: visitCreatePassword | D16: Screen | E16: CreatePasswordScreen
B17: Prelogin | C17: visitPreLoginBinded | D17: Screen | E17: PreloginBindedScreen | H17: PreloginBindedScreen
B18: Prelogin | C18: visitPreLoginUnbinded | D18: Screen | E18: PreloginUnbindedScreen
B19: Prelogin | C19: hitPreloginTransfer | D19: Event · hit | E19: Prelogin_Transfer_Tapped
B20: Prelogin | C20: hitPreloginTarikTunai | D20: Event · hit | E20: Prelogin_TarikTunai_Tapped
B21: Prelogin | C21: hitPreloginPinToken | D21: Event · hit | E21: Prelogin_PINTokenIB_Tapped
B22: Prelogin | C22: hitPreloginScanQR | D22: Event · hit | E22: Prelogin_ScanQR_Tapped
B23: Prelogin | C23: hitPreloginCarouselLink | D23: Event · hit | E23: PreloginBinded_Carousel_Link_Tapped | J23: item_code
B24: Prelogin | C24: hitPreloginLogin | D24: Event · hit | E24: PreloginBinded_Login_Tapped | G24: Login
B25: Prelogin | C25: hitPreloginLanguage | D25: Event · hit | E25: Prelogin_Language_Tapped | J25: category_name
B26: Prelogin | C26: hitPreloginLanguageItem | D26: Event · hit | E26: Prelogin_Language_Item_Tapped | J26: item_code, category_name
B27: Dashboard | C27: visitDashboard | D27: Screen | E27: DashboardScreen | F27: dashboard viewed | I27: DashboardScreen
B28: Dashboard | C28: hitDashboardTabHome | D28: Event · hit | E28: Dashboard_Tab_Home_Tapped | F28: dashboard home clicked
B29: Dashboard | C29: hitDashboardTabQr | D29: Event · hit | E29: Dashboard_Tab_QR_Tapped | F29: dashboard qris clicked
B30: Dashboard | C30: hitDashboardTabRewards | D30: Event · hit | E30: Dashboard_Tab_Rewards_Tapped | F30: dashboard rewards clicked
B31: Dashboard | C31: hitDashboardTabMore | D31: Event · hit | E31: Dashboard_Tab_More_Tapped | F31: dashboard more clicked
B32: Dashboard | C32: hitQuickMenuChange | D32: Event · hit | E32: QuickMenu_Change_Clicked | F32: favorite quickmenu edit button clicked
B33: Dashboard | C33: hitQuickMenu | D33: Event · hit | E33: QuickMenu_Item_Clicked | F33: quickmenu clicked | J33: item_title, code, menu, is_favorite
B34: Dashboard | C34: visitDashboardTaskListWidget | D34: Screen | E34: Dashboard_TaskList_Widget_Shown
B35: More | C35: visitMoreScreen | D35: Screen | E35: MoreScreen
B36: More | C36: hitMoreMenu | D36: Event · hit | E36: More_Menu_Item_Clicked | J36: item_title, code
B37: Transaction Receipt | C37: visitTransactionReceipt | D37: Screen | E37: TransactionReceiptScreen | F37: transaction receipt | G37: TransactionReceiptScreen | I37: TransactionReceipt%@%@%@Screen | J37: receipt_id, receipt_code, receipt_name, receipt_status, receipt_amount, item_type, transaction_id, evergageIdentifier, evergageCode, evergageType, evergageStatus
B38: Transaction Receipt | C38: hitShareReceipt | D38: Event · hit | E38: TransactionReceipt_Share_Tapped
B39: Eazy Pro | C39: visitEazyProLifeInsured | D39: Screen | E39: EazyProLife_Insured_Screen | J39: product_code
B40: Eazy Pro | C40: hitEazyProLifeInsuredNext | D40: Event · hit | E40: EazyProLife_Insured_Next_Tapped | J40: product_code
B41: Eazy Pro | C41: visitEazyProLifeInheritor | D41: Screen | E41: EazyProLife_Inheritor_Screen
...

Sheet PROGRESS
A1: PROGRESS
A2: Counts ticks in SUMMARY. Updates automatically.
B4: Done | C4: Total | D4: Progress
A5: Screens | B5: =COUNTIFS(SUMMARY!$D$5:$D$48,"Screen",SUMMARY!$A$5:$A$48,"✓") -> 0 | C5: =COUNTIF(SUMMARY!$D$5:$D$48,"Screen") -> 18 | D5: =IFERROR(B5/C5,0) -> 0
A6: Events | B6: =COUNTIFS(SUMMARY!$D$5:$D$48,"<>Screen",SUMMARY!$A$5:$A$48,"✓") -> 0 | C6: =COUNTIF(SUMMARY!$D$5:$D$48,"<>Screen") -> 26 | D6: =IFERROR(B6/C6,0) -> 0
A7: All keys | B7: =COUNTIF(SUMMARY!$A$5:$A$48,"✓") -> 0 | C7: =ROWS(SUMMARY!$A$5:$A$48) -> 44 | D7: =IFERROR(B7/C7,0) -> 0
A10: Feature | B10: Screens done | C10: Screens | D10: Events done | E10: Events | F10: Done | G10: Total | H10: Progress
A11: Login | B11: =COUNTIFS(SUMMARY!$B$5:$B$48,$A11,SUMMARY!$D$5:$D$48,"Screen",SUMMARY!$A$5:$A$48,"✓") -> 0 | C11: =COUNTIFS(SUMMARY!$B$5:$B$48,$A11,SUMMARY!$D$5:$D$48,"Screen") -> 2 | D11: =COUNTIFS(SUMMARY!$B$5:$B$48,$A11,SUMMARY!$D$5:$D$48,"<>Screen",SUMMARY!$A$5:$A$48,"✓") -> 0 | E11: =COUNTIFS(SUMMARY!$B$5:$B$48,$A11,SUMMARY!$D$5:$D$48,"<>Screen") -> 4 | F11: =B11+D11 -> 0 | G11: =C11+E11 -> 6 | H11: =IFERROR(F11/G11,0) -> 0
A12: Intro Biometric | B12: =COUNTIFS(SUMMARY!$B$5:$B$48,$A12,SUMMARY!$D$5:$D$48,"Screen",SUMMARY!$A$5:$A$48,"✓") -> 0 | C12: =COUNTIFS(SUMMARY!$B$5:$B$48,$A12,SUMMARY!$D$5:$D$48,"Screen") -> 1 | D12: =COUNTIFS(SUMMARY!$B$5:$B$48,$A12,SUMMARY!$D$5:$D$48,"<>Screen",SUMMARY!$A$5:$A$48,"✓") -> 0 | E12: =COUNTIFS(SUMMARY!$B$5:$B$48,$A12,SUMMARY!$D$5:$D$48,"<>Screen") -> 2 | F12: =B12+D12 -> 0 | G12: =C12+E12 -> 3 | H12: =IFERROR(F12/G12,0) -> 0
A13: Registration | B13: =COUNTIFS(SUMMARY!$B$5:$B$48,$A13,SUMMARY!$D$5:$D$48,"Screen",SUMMARY!$A$5:$A$48,"✓") -> 0 | C13: =COUNTIFS(SUMMARY!$B$5:$B$48,$A13,SUMMARY!$D$5:$D$48,"Screen") -> 1 | D13: =COUNTIFS(SUMMARY!$B$5:$B$48,$A13,SUMMARY!$D$5:$D$48,"<>Screen",SUMMARY!$A$5:$A$48,"✓") -> 0 | E13: =COUNTIFS(SUMMARY!$B$5:$B$48,$A13,SUMMARY!$D$5:$D$48,"<>Screen") -> 1 | F13: =B13+D13 -> 0 | G13: =C13+E13 -> 2 | H13: =IFERROR(F13/G13,0) -> 0
A14: Create Password | B14: =COUNTIFS(SUMMARY!$B$5:$B$48,$A14,SUMMARY!$D$5:$D$48,"Screen",SUMMARY!$A$5:$A$48,"✓") -> 0 | C14: =COUNTIFS(SUMMARY!$B$5:$B$48,$A14,SUMMARY!$D$5:$D$48,"Screen") -> 1 | D14: =COUNTIFS(SUMMARY!$B$5:$B$48,$A14,SUMMARY!$D$5:$D$48,"<>Screen",SUMMARY!$A$5:$A$48,"✓") -> 0 | E14: =COUNTIFS(SUMMARY!$B$5:$B$48,$A14,SUMMARY!$D$5:$D$48,"<>Screen") -> 0 | F14: =B14+D14 -> 0 | G14: =C14+E14 -> 1 | H14: =IFERROR(F14/G14,0) -> 0
A15: Prelogin | B15: =COUNTIFS(SUMMARY!$B$5:$B$48,$A15,SUMMARY!$D$5:$D$48,"Screen",SUMMARY!$A$5:$A$48,"✓") -> 0 | C15: =COUNTIFS(SUMMARY!$B$5:$B$48,$A15,SUMMARY!$D$5:$D$48,"Screen") -> 2 | D15: =COUNTIFS(SUMMARY!$B$5:$B$48,$A15,SUMMARY!$D$5:$D$48,"<>Screen",SUMMARY!$A$5:$A$48,"✓") -> 0 | E15: =COUNTIFS(SUMMARY!$B$5:$B$48,$A15,SUMMARY!$D$5:$D$48,"<>Screen") -> 8 | F15: =B15+D15 -> 0 | G15: =C15+E15 -> 10 | H15: =IFERROR(F15/G15,0) -> 0
A16: Dashboard | B16: =COUNTIFS(SUMMARY!$B$5:$B$48,$A16,SUMMARY!$D$5:$D$48,"Screen",SUMMARY!$A$5:$A$48,"✓") -> 0 | C16: =COUNTIFS(SUMMARY!$B$5:$B$48,$A16,SUMMARY!$D$5:$D$48,"Screen") -> 2 | D16: =COUNTIFS(SUMMARY!$B$5:$B$48,$A16,SUMMARY!$D$5:$D$48,"<>Screen",SUMMARY!$A$5:$A$48,"✓") -> 0 | E16: =COUNTIFS(SUMMARY!$B$5:$B$48,$A16,SUMMARY!$D$5:$D$48,"<>Screen") -> 6 | F16: =B16+D16 -> 0 | G16: =C16+E16 -> 8 | H16: =IFERROR(F16/G16,0) -> 0
A17: More | B17: =COUNTIFS(SUMMARY!$B$5:$B$48,$A17,SUMMARY!$D$5:$D$48,"Screen",SUMMARY!$A$5:$A$48,"✓") -> 0 | C17: =COUNTIFS(SUMMARY!$B$5:$B$48,$A17,SUMMARY!$D$5:$D$48,"Screen") -> 1 | D17: =COUNTIFS(SUMMARY!$B$5:$B$48,$A17,SUMMARY!$D$5:$D$48,"<>Screen",SUMMARY!$A$5:$A$48,"✓") -> 0 | E17: =COUNTIFS(SUMMARY!$B$5:$B$48,$A17,SUMMARY!$D$5:$D$48,"<>Screen") -> 1 | F17: =B17+D17 -> 0 | G17: =C17+E17 -> 2 | H17: =IFERROR(F17/G17,0) -> 0
A18: Transaction Receipt | B18: =COUNTIFS(SUMMARY!$B$5:$B$48,$A18,SUMMARY!$D$5:$D$48,"Screen",SUMMARY!$A$5:$A$48,"✓") -> 0 | C18: =COUNTIFS(SUMMARY!$B$5:$B$48,$A18,SUMMARY!$D$5:$D$48,"Screen") -> 1 | D18: =COUNTIFS(SUMMARY!$B$5:$B$48,$A18,SUMMARY!$D$5:$D$48,"<>Screen",SUMMARY!$A$5:$A$48,"✓") -> 0 | E18: =COUNTIFS(SUMMARY!$B$5:$B$48,$A18,SUMMARY!$D$5:$D$48,"<>Screen") -> 1 | F18: =B18+D18 -> 0 | G18: =C18+E18 -> 2 | H18: =IFERROR(F18/G18,0) -> 0
A19: Eazy Pro | B19: =COUNTIFS(SUMMARY!$B$5:$B$48,$A19,SUMMARY!$D$5:$D$48,"Screen",SUMMARY!$A$5:$A$48,"✓") -> 0 | C19: =COUNTIFS(SUMMARY!$B$5:$B$48,$A19,SUMMARY!$D$5:$D$48,"Screen") -> 2 | D19: =COUNTIFS(SUMMARY!$B$5:$B$48,$A19,SUMMARY!$D$5:$D$48,"<>Screen",SUMMARY!$A$5:$A$48,"✓") -> 0 | E19: =COUNTIFS(SUMMARY!$B$5:$B$48,$A19,SUMMARY!$D$5:$D$48,"<>Screen") -> 2 | F19: =B19+D19 -> 0 | G19: =C19+E19 -> 4 | H19: =IFERROR(F19/G19,0) -> 0
A20: Live Smart | B20: =COUNTIFS(SUMMARY!$B$5:$B$48,$A20,SUMMARY!$D$5:$D$48,"Screen",SUMMARY!$A$5:$A$48,"✓") -> 0 | C20: =COUNTIFS(SUMMARY!$B$5:$B$48,$A20,SUMMARY!$D$5:$D$48,"Screen") -> 1 | D20: =COUNTIFS(SUMMARY!$B$5:$B$48,$A20,SUMMARY!$D$5:$D$48,"<>Screen",SUMMARY!$A$5:$A$48,"✓") -> 0 | E20: =COUNTIFS(SUMMARY!$B$5:$B$48,$A20,SUMMARY!$D$5:$D$48,"<>Screen") -> 0 | F20: =B20+D20 -> 0 | G20: =C20+E20 -> 1 | H20: =IFERROR(F20/G20,0) -> 0
A21: Error | B21: =COUNTIFS(SUMMARY!$B$5:$B$48,$A21,SUMMARY!$D$5:$D$48,"Screen",SUMMARY!$A$5:$A$48,"✓") -> 0 | C21: =COUNTIFS(SUMMARY!$B$5:$B$48,$A21,SUMMARY!$D$5:$D$48,"Screen") -> 1 | D21: =COUNTIFS(SUMMARY!$B$5:$B$48,$A21,SUMMARY!$D$5:$D$48,"<>Screen",SUMMARY!$A$5:$A$48,"✓") -> 0 | E21: =COUNTIFS(SUMMARY!$B$5:$B$48,$A21,SUMMARY!$D$5:$D$48,"<>Screen") -> 1 | F21: =B21+D21 -> 0 | G21: =C21+E21 -> 2 | H21: =IFERROR(F21/G21,0) -> 0
A22: Call Waiting | B22: =COUNTIFS(SUMMARY!$B$5:$B$48,$A22,SUMMARY!$D$5:$D$48,"Screen",SUMMARY!$A$5:$A$48,"✓") -> 0 | C22: =COUNTIFS(SUMMARY!$B$5:$B$48,$A22,SUMMARY!$D$5:$D$48,"Screen") -> 1 | D22: =COUNTIFS(SUMMARY!$B$5:$B$48,$A22,SUMMARY!$D$5:$D$48,"<>Screen",SUMMARY!$A$5:$A$48,"✓") -> 0 | E22: =COUNTIFS(SUMMARY!$B$5:$B$48,$A22,SUMMARY!$D$5:$D$48,"<>Screen") -> 0 | F22: =B22+D22 -> 0 | G22: =C22+E22 -> 1 | H22: =IFERROR(F22/G22,0) -> 0
A23: Video Verification | B23: =COUNTIFS(SUMMARY!$B$5:$B$48,$A23,SUMMARY!$D$5:$D$48,"Screen",SUMMARY!$A$5:$A$48,"✓") -> 0 | C23: =COUNTIFS(SUMMARY!$B$5:$B$48,$A23,SUMMARY!$D$5:$D$48,"Screen") -> 2 | D23: =COUNTIFS(SUMMARY!$B$5:$B$48,$A23,SUMMARY!$D$5:$D$48,"<>Screen",SUMMARY!$A$5:$A$48,"✓") -> 0 | E23: =COUNTIFS(SUMMARY!$B$5:$B$48,$A23,SUMMARY!$D$5:$D$48,"<>Screen") -> 0 | F23: =B23+D23 -> 0 | G23: =C23+E23 -> 2 | H23: =IFERROR(F23/G23,0) -> 0
